<robot name="two_wheeled_robot">
  <!-- Base Link -->
  <link name="base_link">
    <visual>
      <geometry>
        <box size="0.11 0.08 0.1"/>
      </geometry>
    </visual>
    <collision>
      <geometry>
        <box size="0.12 0.08 0.1"/>
      </geometry>
    </collision>
    <inertial>
      <mass value="1"/>
      <inertia ixx="0.001" ixy="0.0" ixz="0.0" iyy="0.001" iyz="0.0" izz="0.001"/>
    </inertial>
  </link>
  <!-- LIDAR Link -->
  <link name="lidar">
    <visual>
      <geometry>
        <cylinder radius="0.02" length="0.025"/>
      </geometry>
      <origin rpy="0 0 0" xyz="0 0 0"/>
      <material name="blue">
        <color rgba="0 0 1 1"/>
      </material>
    </visual>
    <collision>
      <geometry>
        <cylinder radius="0.02" length="0.025"/>
      </geometry>
    </collision>
    <inertial>
      <mass value="0.1"/>
      <inertia ixx="0.0001" ixy="0.0" ixz="0.0" iyy="0.0001" iyz="0.0" izz="0.0001"/>
    </inertial>
  </link>
  <!-- Wheel Links -->
  <link name="left_wheel">
    <visual>
      <geometry>
        <cylinder radius="0.03" length="0.0075"/>
      </geometry>
      <material name="black"/>
    </visual>
    <collision>
      <geometry>
        <cylinder radius="0.03" length="0.0075"/>
      </geometry>
    </collision>
    <inertial>
      <mass value="0.1"/>
      <inertia ixx="0.0001" ixy="0.0" ixz="0.0" iyy="0.0001" iyz="0.0" izz="0.0001"/>
    </inertial>
  </link>
  <link name="right_wheel">
    <visual>
      <geometry>
        <cylinder radius="0.03" length="0.0075"/>
      </geometry>
      <material name="black">
        <color rgba="0.2 0.2 0.2 1"/>
      </material>
    </visual>
    <collision>
      <geometry>
        <cylinder radius="0.03" length="0.075"/>
      </geometry>
    </collision>
    <inertial>
      <mass value="0.1"/>
      <inertia ixx="0.0001" ixy="0.0" ixz="0.0" iyy="0.0001" iyz="0.0" izz="0.0001"/>
    </inertial>
  </link>
  <!--Caster Cylinder Link-->
  <link name="caster_cylinder">
    <visual>
      <geometry>
        <cylinder radius="0.01" length="0.025"/>
      </geometry>
    </visual>
    <collision>
      <geometry>
        <cylinder radius="0.01" length="0.025"/>
      </geometry>
    </collision>
    <inertial>
      <mass value="0.05"/>
      <inertia ixx="0.001" ixy="0.0001" ixz="0.0" iyy="0.0" iyz="0.0" izz="0.0"/>
    </inertial>
  </link>
  <!-- Caster Link -->
  <link name="caster">
    <visual>
      <geometry>
        <sphere radius="0.01"/>
      </geometry>
    </visual>
    <collision>
      <geometry>
        <sphere radius="0.01"/>
      </geometry>
    </collision>
    <inertial>
      <mass value="0.05"/>
      <inertia ixx="0.0000125" ixy="0.0" ixz="0.0" iyy="0.0000125" iyz="0.0" izz="0.0000125"/>
    </inertial>
  </link>
  <!-- Joint Definitions -->
  <!-- LIDAR Joint -->
  <joint name="lidar_joint" type="fixed">
    <parent link="base_link"/>
    <child link="lidar"/>
    <origin xyz="0 0 0.0625" rpy="0 0 0"/>
  </joint>
  <joint name="left_wheel_joint" type="continuous">
    <parent link="base_link"/>
    <child link="left_wheel"/>
    <origin xyz="-0.0125 -0.04375 -0.05" rpy="1.57075 0 0"/>
    <axis xyz="0 1 0"/>
  </joint>
  <joint name="right_wheel_joint" type="continuous">
    <parent link="base_link"/>
    <child link="right_wheel"/>
    <origin xyz="-0.0125 0.04375 -0.05" rpy="1.57075 0 0"/>
    <axis xyz="0 1 0"/>
  </joint>
  <joint name="cylinder_joint" type="fixed">
    <parent link="base_link"/>
    <child link="caster_cylinder"/>
    <origin xyz="0.0375 0 -0.05125" rpy="0 0 0"/>
    <axis xyz="0 1 0"/>
  </joint>
  <joint name="caster_joint" type="floating">
    <parent link="caster_cylinder"/>
    <child link="caster"/>
    <origin xyz="0 0 -0.0125" rpy="0 0 0"/>
  </joint>
</robot>