<?xml version="1.0"?>
<robot name="two_wheeled_robot">
  <!-- Base Link -->
  <link name="base_link">
    <visual>
      <geometry>
        <box size="0.11 0.08 0.1"/>
      <material name="blue">
        <color rgba="0 0 1 1"/>
      </material>
      </geometry>
    </visual>
    <collision>
      <geometry>
        <box size="0.11 0.08 0.1"/>
      </geometry>
    </collision>
    <inertial>
      <mass value="1"/>
      <inertia ixx="0.001" ixy="0.0" ixz="0.0" iyy="0.001" iyz="0.0" izz="0.001"/>
    </inertial>
  </link>
  <!-- Base Footprint Link -->
  <link name="base_footprint">
    <inertial>    
      <mass value="0"/>
      <inertia ixx="0.0" ixy="0.0" ixz="0.0" iyy="0.0" iyz="0.0" izz="0.0"/>
    </inertial>
  </link>
  <!-- LIDAR Link -->
  <link name="lidar_link">
    <visual>
      <geometry>
        <cylinder radius="0.02" length="0.025"/>
      </geometry>
      <origin rpy="0 0 0" xyz="0 0 0"/>
      <material name="blue">
        <color rgba="0 0 1 1"/>
      </material>
    </visual>
    <collision>
      <geometry>
        <cylinder radius="0.02" length="0.025"/>
      </geometry>
    </collision>
    <inertial>
      <mass value="0.1"/>
      <inertia ixx="0.0001" ixy="0.0" ixz="0.0" iyy="0.0001" iyz="0.0" izz="0.0001"/>
    </inertial>
  </link>
  <!-- Wheel Links -->
  <link name="left_wheel">
    <visual>
      <geometry>
        <cylinder radius="0.03" length="0.0075"/>
      </geometry>
      <material name="cyan">
        <color rgba="0 1 1 1"/>
      </material>
    </visual>
    <collision>
      <geometry>
        <cylinder radius="0.03" length="0.0075"/>
      </geometry>
    </collision>
    <inertial>
      <mass value="0.1"/>
      <inertia ixx="0.000045" ixy="0.0" ixz="0.0" iyy="0.000045" iyz="0.0" izz="0.000045"/>
    </inertial>
  </link>
  <link name="right_wheel">
    <visual>
      <geometry>
        <cylinder radius="0.03" length="0.0075"/>
      </geometry>
      <material name="cyan">
        <color rgba="0 1 1 1"/>
      </material>
    </visual>
    <collision>
      <geometry>
        <cylinder radius="0.03" length="0.075"/>
      </geometry>
    </collision>
    <inertial>
      <mass value="0.1"/>
      <inertia ixx="0.000045" ixy="0.0" ixz="0.0" iyy="0.000045" iyz="0.0" izz="0.000045"/>
    </inertial>
  </link>
  <!--Caster Cylinder Link-->
  <link name="caster_cylinder">
    <visual>
      <geometry>
        <cylinder radius="0.01" length="0.01"/>
      </geometry>
    </visual>
    <collision>
      <geometry>
        <cylinder radius="0.01" length="0.01"/>
      </geometry>
    </collision>
    <inertial>
      <mass value="0.05"/>
       <inertia ixx="0.00000167" ixy="0.0" ixz="0.0" iyy="0.00000167" iyz="0.0" izz="0.0000025"/>
    </inertial>
  </link>
  <!-- Caster Link -->
  <link name="caster">
    <visual>
      <geometry>
        <sphere radius="0.02"/>
      </geometry>
    </visual>
    <collision>
      <geometry>
        <sphere radius="0.02"/>
      </geometry>
    </collision>
    <inertial>
      <mass value="0.05"/>
      <inertia ixx="0.000002" ixy="0.0" ixz="0.0" iyy="0.000002" iyz="0.0" izz="0.000002"/>
    </inertial>
  </link>
  <!-- Joint Definitions -->
  <!-- Base Joint -->
  <joint name="base_joint" type="fixed">
    <parent link="base_link"/>
    <child link="base_footprint"/>
    <origin xyz="0 0 -0.08" rpy="0 0 0"/>
  </joint>
  <!-- LIDAR Joint -->
  <joint name="lidar_joint" type="fixed">
    <parent link="base_link"/>
    <child link="lidar_link"/>
    <origin xyz="0 0 0.0625" rpy="0 0 0"/>
  </joint>
  <!-- Wheels Joint -->
  <joint name="left_wheel_joint" type="continuous">
    <parent link="base_link"/>
    <child link="left_wheel"/>
    <origin xyz="-0.0125 -0.04375 -0.05" rpy="1.57075 0 0"/>
    <axis xyz="0 0 -1"/>
  </joint>
  <joint name="right_wheel_joint" type="continuous">
    <parent link="base_link"/>
    <child link="right_wheel"/>
    <origin xyz="-0.0125 0.04375 -0.05" rpy="1.57075 0 0"/>
    <axis xyz="0 0 -1"/>
  </joint>
  <!-- Cylinder Caster Joint -->
  <joint name="cylinder_joint" type="fixed">
    <parent link="base_link"/>
    <child link="caster_cylinder"/>
    <origin xyz="0.0375 0 -0.055" rpy="0 0 0"/>
  </joint>
  <joint name="caster_joint" type="fixed">
    <parent link="base_link"/>
    <child link="caster"/>
    <origin xyz="0.0375 0 -0.06" rpy="0 0 0"/>
    <axis xyz="1 1 1"/>
  </joint>
  <!-- Gazebo plugin for differential drive -->
  <gazebo>
    <plugin name="diff_drive" filename="libgazebo_ros_diff_drive.so">
      <update_rate>100.0</update_rate>
      <left_joint>left_wheel_joint</left_joint>
      <right_joint>right_wheel_joint</right_joint>
      <wheel_separation>0.0875</wheel_separation>
      <wheel_diameter>0.06</wheel_diameter>
      <max_wheel_torque>0.5</max_wheel_torque>
      <max_wheel_acceleration>0.0025</max_wheel_acceleration>
      <!-- output -->
      <publish_odom>true</publish_odom>
      <publish_odom_tf>false</publish_odom_tf>
      <publish_wheel_tf>true</publish_wheel_tf>
      <odometry_frame>odom</odometry_frame>
      <robot_base_frame>base_link</robot_base_frame>
    </plugin>
  </gazebo>
  <!-- Gazebo plugin for RPLIDAR A1 -->
  <gazebo reference="lidar_link">
    <sensor name="lidar" type="ray">
      <always_on>true</always_on>
      <visualize>true</visualize>
      <update_rate>1</update_rate>
      <ray>
        <scan>
          <horizontal>
            <samples>180</samples>
            <resolution>1.000000</resolution>
            <min_angle>0.000000</min_angle>
            <max_angle>6.28319</max_angle>
          </horizontal>
        </scan>
        <range>
          <min>0.120000</min>
          <max>3.5</max>
          <resolution>0.015000</resolution>
        </range>
        <noise>
          <type>gaussian</type>
          <mean>0.0</mean>
          <stddev>0.01</stddev>
        </noise>
      </ray>
      <plugin name="scan" filename="libgazebo_ros_ray_sensor.so">
        <ros>
          <remapping>~/out:=scan</remapping>
        </ros>
        <output_type>sensor_msgs/LaserScan</output_type>
        <frame_name>lidar_link</frame_name>
      </plugin>
    </sensor>
  </gazebo>
</robot>